<mujoco model="reacher">
    <compiler angle="radian" inertiafromgeom="auto"/>
    <default>
        <joint armature="0.01" damping="0.1" limited="true" frictionloss="0.5"/>
        <geom friction="0.1 0.1 0.1" rgba="0.7 0.7 0 1" condim="3" density="10"/>
    </default>
    <option gravity="0 0 -9.81" integrator="RK4" timestep="0.05" noslip_iterations="5"/>

    <worldbody>
        <!-- Arena -->
        <geom type="plane" name="ground" pos="0 0 0" size="5 5 10" rgba="0.9 0.9 0.9 1"/>
        <geom type="capsule" fromto="-2 -2 .1 2 -2 .1" size=".2" rgba="0.9 0.4 0.6 1"/>
        <geom type="capsule" fromto="2 -2 .1 2 2 .1" size=".2" rgba="0.9 0.4 0.6 1"/>
        <geom type="capsule" fromto="-2 2 .1 2 2 .1" size=".2" rgba="0.9 0.4 0.6 1"/>
        <geom type="capsule" fromto="-2 -2 .1 -2 2 .1" size=".2" rgba="0.9 0.4 0.6 1"/>

        <!-- Arm -->
        <geom type="cylinder" fromto="0 0 0 0 0 0.4" size=".11" rgba="0.9 0.4 0.6 1"/>
        <body name="body0" pos="0 0 .2">
            <geom type="capsule" fromto="0 0 0 0.75 0 0" size=".1" rgba="0.0 0.4 0.6 1"/>
            <joint type="hinge" axis="0 0 1" name="joint0" limited="false" pos="0 0 0"/>
            <body name="body1" pos="0.75 0 0">
                <geom type="capsule" fromto="0 0 0 0.75 0 0" size=".1" rgba="0.0 0.4 0.6 1"/>
                <joint type="hinge" axis="0 0 1" name="joint1" limited="true" range="-3.0 3.0" pos="0 0 0"/>
                <body name="fingertip" pos="0.85 0 0">
                    <geom type="sphere" name="fingertip" size="0.1" rgba="0.0 0.8 0.6 1"/>
                </body>
            </body>
        </body>

        <!-- Target: safe within reach -->
        <body name="target" pos="1.2 0.0 0.2">
            <geom type="sphere" size="0.1" rgba="0 0.9 0 1" contype="1" conaffinity="1"/>
        </body>

        
    </worldbody>

    <actuator>
        <motor joint="joint0" gear="1.0" ctrllimited="true" ctrlrange="-1.0 1.0"/>
        <motor joint="joint1" gear="1.0" ctrllimited="true" ctrlrange="-1.0 1.0"/>
    </actuator>
</mujoco>
